Traceback (most recent call last):
  File "C:\Users\noibar\anaconda3\envs\geo_env\lib\site-packages\jupyter_cache\executors\utils.py", line 51, in single_nb_execution
    executenb(
  File "C:\Users\noibar\anaconda3\envs\geo_env\lib\site-packages\nbclient\client.py", line 1204, in execute
    return NotebookClient(nb=nb, resources=resources, km=km, **kwargs).execute()
  File "C:\Users\noibar\anaconda3\envs\geo_env\lib\site-packages\nbclient\util.py", line 84, in wrapped
    return just_run(coro(*args, **kwargs))
  File "C:\Users\noibar\anaconda3\envs\geo_env\lib\site-packages\nbclient\util.py", line 62, in just_run
    return loop.run_until_complete(coro)
  File "C:\Users\noibar\anaconda3\envs\geo_env\lib\asyncio\base_events.py", line 646, in run_until_complete
    return future.result()
  File "C:\Users\noibar\anaconda3\envs\geo_env\lib\site-packages\nbclient\client.py", line 663, in async_execute
    await self.async_execute_cell(
  File "C:\Users\noibar\anaconda3\envs\geo_env\lib\site-packages\nbclient\client.py", line 965, in async_execute_cell
    await self._check_raise_for_error(cell, cell_index, exec_reply)
  File "C:\Users\noibar\anaconda3\envs\geo_env\lib\site-packages\nbclient\client.py", line 862, in _check_raise_for_error
    raise CellExecutionError.from_cell_and_msg(cell, exec_reply_content)
nbclient.exceptions.CellExecutionError: An error occurred while executing the following cell:
------------------
gdb_file = 'fire21_1.gdb'

# Get all the layers from the .gdb file 
layers = fiona.listlayers(gdb_file)

for layer in layers:
  if layer == 'firep21_1': # there are 3 files in gdb, we only need one
    print(f'found file: {layer}')
    fires = gpd.read_file(gdb_file,layer=layer)
------------------

[1;31m---------------------------------------------------------------------------[0m
[1;31mCPLE_OpenFailedError[0m                      Traceback (most recent call last)
File [1;32mfiona\_shim.pyx:83[0m, in [0;36mfiona._shim.gdal_open_vector[1;34m()[0m

File [1;32mfiona\_err.pyx:291[0m, in [0;36mfiona._err.exc_wrap_pointer[1;34m()[0m

[1;31mCPLE_OpenFailedError[0m: fire21_1.gdb: No such file or directory

During handling of the above exception, another exception occurred:

[1;31mDriverError[0m                               Traceback (most recent call last)
Input [1;32mIn [6][0m, in [0;36m<cell line: 4>[1;34m()[0m
[0;32m      1[0m gdb_file [38;5;241m=[39m [38;5;124m'[39m[38;5;124mfire21_1.gdb[39m[38;5;124m'[39m
[0;32m      3[0m [38;5;66;03m# Get all the layers from the .gdb file [39;00m
[1;32m----> 4[0m layers [38;5;241m=[39m [43mfiona[49m[38;5;241;43m.[39;49m[43mlistlayers[49m[43m([49m[43mgdb_file[49m[43m)[49m
[0;32m      6[0m [38;5;28;01mfor[39;00m layer [38;5;129;01min[39;00m layers:
[0;32m      7[0m   [38;5;28;01mif[39;00m layer [38;5;241m==[39m [38;5;124m'[39m[38;5;124mfirep21_1[39m[38;5;124m'[39m: [38;5;66;03m# there are 3 files in gdb, we only need one[39;00m

File [1;32m~\anaconda3\envs\geo_env\lib\site-packages\fiona\env.py:417[0m, in [0;36mensure_env_with_credentials.<locals>.wrapper[1;34m(*args, **kwargs)[0m
[0;32m    415[0m [38;5;28;01mwith[39;00m Env[38;5;241m.[39mfrom_defaults(session[38;5;241m=[39msession):
[0;32m    416[0m     log[38;5;241m.[39mdebug([38;5;124m"[39m[38;5;124mCredentialized: [39m[38;5;132;01m{!r}[39;00m[38;5;124m"[39m[38;5;241m.[39mformat(getenv()))
[1;32m--> 417[0m     [38;5;28;01mreturn[39;00m f([38;5;241m*[39margs, [38;5;241m*[39m[38;5;241m*[39mkwargs)

File [1;32m~\anaconda3\envs\geo_env\lib\site-packages\fiona\__init__.py:362[0m, in [0;36mlistlayers[1;34m(fp, vfs)[0m
[0;32m    359[0m [38;5;28;01melse[39;00m:
[0;32m    360[0m     pobj [38;5;241m=[39m parse_path(fp)
[1;32m--> 362[0m [38;5;28;01mreturn[39;00m [43m_listlayers[49m[43m([49m[43mvsi_path[49m[43m([49m[43mpobj[49m[43m)[49m[43m)[49m

File [1;32mfiona\ogrext.pyx:1659[0m, in [0;36mfiona.ogrext._listlayers[1;34m()[0m

File [1;32mfiona\_shim.pyx:90[0m, in [0;36mfiona._shim.gdal_open_vector[1;34m()[0m

[1;31mDriverError[0m: fire21_1.gdb: No such file or directory
DriverError: fire21_1.gdb: No such file or directory

