Traceback (most recent call last):
  File "C:\Users\barguzin\anaconda3\envs\geo_env\lib\site-packages\jupyter_cache\executors\utils.py", line 51, in single_nb_execution
    executenb(
  File "C:\Users\barguzin\anaconda3\envs\geo_env\lib\site-packages\nbclient\client.py", line 1204, in execute
    return NotebookClient(nb=nb, resources=resources, km=km, **kwargs).execute()
  File "C:\Users\barguzin\anaconda3\envs\geo_env\lib\site-packages\nbclient\util.py", line 84, in wrapped
    return just_run(coro(*args, **kwargs))
  File "C:\Users\barguzin\anaconda3\envs\geo_env\lib\site-packages\nbclient\util.py", line 62, in just_run
    return loop.run_until_complete(coro)
  File "C:\Users\barguzin\anaconda3\envs\geo_env\lib\asyncio\base_events.py", line 646, in run_until_complete
    return future.result()
  File "C:\Users\barguzin\anaconda3\envs\geo_env\lib\site-packages\nbclient\client.py", line 663, in async_execute
    await self.async_execute_cell(
  File "C:\Users\barguzin\anaconda3\envs\geo_env\lib\site-packages\nbclient\client.py", line 965, in async_execute_cell
    await self._check_raise_for_error(cell, cell_index, exec_reply)
  File "C:\Users\barguzin\anaconda3\envs\geo_env\lib\site-packages\nbclient\client.py", line 862, in _check_raise_for_error
    raise CellExecutionError.from_cell_and_msg(cell, exec_reply_content)
nbclient.exceptions.CellExecutionError: An error occurred while executing the following cell:
------------------
from pingouin import ttest, mwu
penguins.dropna(inplace=True) # drop null values 
males = penguins.loc[penguins.sex=='MALE', 'flipper_length_mm']
females = penguins.loc[penguins.sex=='FEMALE', 'flipper_length_mm'] 
print(males.shape, females.shape)
ttest(males, females) 
------------------

[1;31m---------------------------------------------------------------------------[0m
[1;31mAssertionError[0m                            Traceback (most recent call last)
Cell [1;32mIn [10], line 6[0m
[0;32m      4[0m females [38;5;241m=[39m penguins[38;5;241m.[39mloc[penguins[38;5;241m.[39msex[38;5;241m==[39m[38;5;124m'[39m[38;5;124mFEMALE[39m[38;5;124m'[39m, [38;5;124m'[39m[38;5;124mflipper_length_mm[39m[38;5;124m'[39m] 
[0;32m      5[0m [38;5;28mprint[39m(males[38;5;241m.[39mshape, females[38;5;241m.[39mshape)
[1;32m----> 6[0m [43mttest[49m[43m([49m[43mmales[49m[43m,[49m[43m [49m[43mfemales[49m[43m)[49m

File [1;32m~\anaconda3\envs\geo_env\lib\site-packages\pingouin\parametric.py:231[0m, in [0;36mttest[1;34m(x, y, paired, alternative, correction, r, confidence)[0m
[0;32m    228[0m     paired [38;5;241m=[39m [38;5;28;01mFalse[39;00m
[0;32m    230[0m [38;5;66;03m# Remove rows with missing values[39;00m
[1;32m--> 231[0m x, y [38;5;241m=[39m [43mremove_na[49m[43m([49m[43mx[49m[43m,[49m[43m [49m[43my[49m[43m,[49m[43m [49m[43mpaired[49m[38;5;241;43m=[39;49m[43mpaired[49m[43m)[49m
[0;32m    232[0m nx, ny [38;5;241m=[39m x[38;5;241m.[39msize, y[38;5;241m.[39msize
[0;32m    234[0m [38;5;28;01mif[39;00m ny [38;5;241m==[39m [38;5;241m1[39m:
[0;32m    235[0m     [38;5;66;03m# Case one sample T-test[39;00m

File [1;32m~\anaconda3\envs\geo_env\lib\site-packages\pingouin\utils.py:236[0m, in [0;36mremove_na[1;34m(x, y, paired, axis)[0m
[0;32m    234[0m [38;5;28;01melse[39;00m:  [38;5;66;03m# y is list, np.array, pd.Series[39;00m
[0;32m    235[0m     y [38;5;241m=[39m np[38;5;241m.[39masarray(y)
[1;32m--> 236[0m     [38;5;28;01massert[39;00m y[38;5;241m.[39msize [38;5;241m!=[39m [38;5;241m0[39m, [38;5;124m"[39m[38;5;124my cannot be an empty list or array.[39m[38;5;124m"[39m
[0;32m    237[0m     [38;5;66;03m# Make sure that we just pass-through if y have only 1 element[39;00m
[0;32m    238[0m     [38;5;28;01mif[39;00m y[38;5;241m.[39msize [38;5;241m==[39m [38;5;241m1[39m:

[1;31mAssertionError[0m: y cannot be an empty list or array.
AssertionError: y cannot be an empty list or array.

